## 47장 에러 처리

### 📌 에러 처리의 필요성
- 에러가 발생하지 않는 코드를 작성하는 것은 불가능하다. 따라서 에러는 언제나 발생할 수 있다. 발생한 에러에 대해 대처하지 않고 방치하면 프로그램은 강제 종료된다.
<br>

### 📌 try...catch...finally 문
- try 코드 블록 실행
- 이때 try 코드 블록에 포함된 문 중에서 에러가 발생하면 발생한 에러는 catch 문의 err 변수에 전달되고 catch 코드 블록이 실행된다.
- catch 문의 err 변수(변수 이름은 무엇이든 상관없다)는 try 코드 블록에 포함된 문 중에서 에러가 발생하면 생성되고 catch 코드 블록에서만 유효하다.
- finally 코드 블록은 에러 발생과 상관없이 반드시 한 번 실행된다.
- try...catch..finally 문으로 에러를 처리하면 프로그램이 강제 종료되지 않는다.
```js
try {
 // 실행할 코드(에러가 발생할 가능성이 있는 코드)
 foo();
} catch (err) {
 // try 코드 블록에서 에러가 발생하면 이 코드 블록의 코드가 실행된다.
 // err에는 try 코드 블록에서 발생한 Error 객체가 전달된다.
 console.error(err); // ReferenceError: foo is not defined
} finally {
 // 에러 발생과 상관없이 반드시 한 번 실행된다.
 console.log('finally');
}
```
### 📌 Error 객체
- Error 생성자 함수는 에러 객체를 생성한다.
- Error 생성자 함수에는 에러를 상세히 설명하는 에러 메시지를 인수로 전달할 수 있다.
```js
const error = new Error('invalid');
```
<br>

### 📌 throw 문
- 에러를 발생시키려면 try 코드 블록에서 throw 문으로 에러 객체를 던져야 한다.
```js
try { 
  // 에러 객체를 던지면 catch 코드 블록이 실행되기 시작한다.
  throw new Error('something wron');
} catch (error) {
  console.log(error);
}
```
<br>

### 📌 에러의 전파

<img src="https://user-images.githubusercontent.com/89966610/183581211-f7cab3c3-0941-4643-a34a-3c9b691e3c6b.png" width=200px />

- throw된 에러를 캐치하지 않으면 호출자 방향으로 전파된다.
- 이때 throw된 에러를 캐치하여 적절히 대응하면 프로그램을 강제 종료시키지 않고 코드의 실행 흐름을 복구할 수 있다.
- throw된 에러를 어디에서도 캐치하지 않으면 프로그램은 강제 종료된다. 
